Workbook

Sheet PersonalInfo
A1: NOTE: This form is not the same as last year's. Please don't copy / paste last year's answers. Taking 30 minutes to read and properly fill this out will save hours of back and forth via email and dramatically reduce the risk of an audit letter from the IRS due to not including something in your return that you should have included.
A2: Planned Filing Status | E2: Filing Status | H2: Yes | K2: Not In US | O2: Version | P2: TY2024.1.0
A3: Expected Filing Status | E3: 1 = Single | H3: No | K3: Alabama
A4: Taxpayer Information | B4: Taxpayer | C4: Spouse | E4: 2 = Married, Filing Jointly | K4: Alaska
A5: First Name & Middle Initial | E5: 3 = Married, Filing Separately | K5: Arizona
A6: Last Name | E6: 4 = Head of Household | K6: Arkansas
A7: Title / Suffix | E7: 5 = Qualified Widow | K7: California
A8: On 12/31, what was your marital status? | K8: Colorado
A9: SSN | K9: Connecticut
A10: Date of Birth (mm/dd/yyyy) | E10: Divorced | K10: Hawaii
A11: Occupation | E11: Married | K11: Florida
A12: Contact Phone Number
A13: Form of Id and Location of Issuance | K13: Connecticut
A14: ID Number | K14: Connecticut
A15: ID Issue Date | K15: Connecticut
A16: ID Expiration Date | K16: Connecticut
A17: NY State Document Number (if it's a NY Driver's License) | E17: Single | K17: Delaware
A18: Address Information | E18: Married | K18: Idaho
A19: Street Address | E19: Divorced | K19: Illinois
A20: Apartment / Unit Number | E20: Widowed | K20: Indiana
A21: City | E21: Legally Separated | K21: Iowa
A22: State | K22: Kansas
A23: Zip | K23: Kentucky
A24: County
A25: Resident of what state as of 12/31?
A26: If you moved during the year, list all states where you resided during the tax year and the date you moved out of that state | K26: Louisiana
A27: Dependent Information | B27: Dependent 1 | C27: Dependent 2 | K27: Michigan
A28: First Name & Middle Initial | K28: Minnesota
A29: Last Name | B29: =IF($B$6="","",IF(B28="","",$B$6)) | C29: =IF($B$6="","",IF(C28="","",$B$6)) | K29: Mississippi
A30: Suffix | K30: Missouri
A31: Date of Birth (mm/dd/yyyy) | K31: Montana
A32: SSN | K32: Nebraska
A33: Relationship to Taypayer | K33: Nevada
A34: Months Lived At Home This Year | K34: New Hampshire
A35: What was your total qualified childcare cost for this dependent? | K35: New Jersey
A36: Did this dependent have any post-secondary tuition expenses? | K36: New Mexico
A37: Is This Dependent ove age 18 and Disabled? | K37: New York
A38: Is This Dependent over age 19 and a Student? | K38: North Carolina
A39: Dependent Information | B39: Dependent 3 | C39: Dependent 4 | K39: North Dakota
A40: First Name & Middle Initial | K40: Ohio
...

Sheet Questionnaire
A1: NOTE: This form is not the same as last year's. Please don't copy / paste last year's answers. Taking 30 minutes to read and properly fill this out will save hours of back and forth via email and dramatically reduce the risk of an audit letter from the IRS due to not including something in your return that you should have included. There were MANY tax changes in 2025 due to the One Big Beautiful Bill. Those who took the standard deduction in 2024 may be able to itemize in 2025. Don't assume you can't unless you know for certain.
A2: Indicate yes/no response with 'x' in the appropriate cell. Provide additional detail in the Comment field as required for each question.
A3: Yes | B3: No | C3: Comment | D3: Question | E3: Links to More Info
A4: Personal Information
D5: I have read the statement in Orange above and agree that I will not copy my answers from last year. If you can't answer "Yes" to this question, please contact us.
D6: If you are due any refunds would you like them to be direct deposited? If yes, list bank name, routing number, account number, and checking or savings in Comment or indicate "Same As Last Year"
D7: If you owe any tax, would you like the amount to be directly debited from your bank account? If yes, list bank name, routing number, account number, and checking or savings in Comment or indicate "Same As Last Year". Note: withdrawal date can be set by you and nothing will be filed before your approval / time to prepare for withdrawal.
D8: Do you want to allocate $3 to the Presidential Election Campaign Fund?
D9: Does your spouse (if applicable) want to allocate $3 to the Presidential Election Campaign Fund?
D10: Did your marital status change during the year? (If yes, indicate from what to what in Comment. If you got divorced or married, please indicate the date of the status change in the Comment as well.
D11: Did your address change during the year? (If yes, list previous address in Comment)
D12: Did you change your state of residence during the year? (If yes, list date you established residence in the new state). Can skip this if you entered this info on the PersonalInfo tab for all states.
D13: Did you have health insurance for you, your spouse, and all dependents for the entire year? Note: The Federal penalty for not having health insurance remained at $0 for 2025, but some states still impose penalties, so please answer the question anyway. If you answer no and it matters for your state, we'll contact you for more info.
D14: Did you enroll in a health plan through your (or your spouse's) employer? If yes, please include Form 1095-B (from insurer, who might be your employer in some cases) and Form 1095-C (from employer) if you received them. Note that the deadline to send these forms may be extended again for tax year 2025 so you may not receive them before filing. We can work around this if you marked "Yes" to the previous question about having insurance for the entire year or if maintaining health coverage is not an issue in your state. MA residents, please also include Form MA-1099-HC | E14: Link to IRS Q&A
D15: Did you enroll in a health plan through a health insurance marketplace (e.g. ACA or Obamacare exchange)? If yes, please include Form 1095-A, which would have been sent to you by the exchange. Unlike 1095B/C, 1095-A is mandatory if for your tax prep if you purchased insurance through an ACA exchange.
D16: Have you created an online tax account with the IRS? Please check Yes if you and/or your spouse (if applicable) has created a tax account. | E16: Link To IRS Online Account
D17: Did you work in any states other than your 12/31 state of residency? (If yes, list the states and provide a breakdown of your earnings by state, unless it is shown on your W-2(s)).
D18: Have you received an Identity Protection PIN (IPPIN) from the IRS (most people haven't, so don't worry if you don't know what this is). If you have, this number is required to EFILE. Please include the IPPIN in the Comment and who it pertains to (taxpayer, spouse, or a child) or include the letter the IRS sent to you with your tax docs. If you signed up for this program, you need a new number every year. | E18: Link to IPPIN Info | F18: Link To IRS Online Account
A19: Dependants
D20: Were there any changes to dependents this year? (If yes, describe in Comment). If you're not sure whether someone is your dependent or not, the link to the right will walk you through a Q/A to determine it. | E20: Link to IRS Dependent Info
D21: Were any of your unmarried children who might be claimed as dependents 19 years of age or older at the end of last year? (If yes, indicate who in Comment)
D22: Did you incur any qualified childcare expenses AND, did you (and your spouse if you're married) have earned income? If yes, please complete the QualifedChildcare tab or provide additional statements with ALL equivalent information. Include childcare costs even if they were reimbursed by a dependent care flexibile spending account (FSA) as that reimbursement must be justified on your return | E22: Link to IRS Pub 503
D23: Did you have any children under age 19 or full-time students under age 24 at the end of the year with investment income in excess of $1350?
D24: Are you planning on opening a “Trump account” for one or more of your dependents as part of your 2025 tax filing? Note: accounts can't be opened until July 2026 and don't have to be opened as part of tax filing. You can also do so via an online portal that will be available by summer 2026. | E24: Link to Details
D25: Did any of your dependents work or earn enough other income to required they file taxes? If yes, and you would like us to file those for them, please list each child's name to which this pertains in the Comment field and we'll contact you for more info. | E25: Link to Q&A
D26: Can you be claimed as a dependent on someone else's return this year? (If yes, who's? Did they claim you?)
A27: Income
D28: Did you receive any disability income? (If yes, please include the W-2, 1099-G, or other document that captures this income)
D29: Did you receive any unemployment income? (If yes, please include the 1099-G)
D30: Did you receive any social security income? (If yes, please include the 1099-SSA)
D31: Did you pay or receive any alimony. (If yes, indicate pay or receive, how much, and the date on which your divorce was final - new for 2019 due to changed tax rules for the way alimony is handled after 12/31/18 - in Comment)
D32: Did you receive any interest from any financial institution? (If yes, please include the 1099-INT for that interest, or list the institutions and interest amounts in the comment field.) Note that a 1099-INT will only be issued if you received >= $10 from the institution and you may have to download it from their website
D33: Did you receive any dividends? (If yes, please include the 1099-DIV or Consolidated 1099-B showing those dividends). If you have brokerage accounts managed by PWA, indicate Yes to this question with "Schwab" in the comment, because dividends have definitely been earned by your account. No form is needed. PWA has access to all Schwab tax docs.
D34: Did you receive any gambling winnings? (If yes, include the amounts, and if applicable, the W-2G that you received. Also include any supporting documentation if you're claiming offsetting gambling losses) | E34: Link to Gambling Tax Rules
D35: Did you receive any rental or royalty income? (If yes, please download and complete a Rental Property Income & Expense Summary xls or pdf from the Tax Prep Documents section of our website). Link Here -------------------------------------------------------> | E35: Link to Rental Worksheet
D36: Did you receive any 1099-MISC, 1099-NEC, 1099-K, or have any other self-employment income? (If yes, please include any 1099-MISC, 1099-NEC, 1099-K, and indicate "No Expenses" in the Comment field or complete a Small Business Income & Expense Summary xls or pdf from the Tax Prep Documents section of our website) Link Here -------------------------------------------------------> | E36: Link to Business Worksheet
D37: Did you receive or do you expect to receive a K-1 for income related to a partnership, S-Corp, or trust in which you own a share? (If yes, and you have received the K-1, please include it with your tax documents. If you expect it but have not received it, indicate "Yes" and list the entity name in the comment field.)
D38: Did you receive any unreported tip income? (If yes, indicate total amount in Comment.)
D39: Did you receive any tip income that qualifies for the "No Tax On Tips" deduction? | E39: Link
D40: Did you receive any overtime that qualifies for the "No Tax On Overtime" deduction? | E40: Link
...

Sheet CharitableContributions
A1: For Cash Contributions:
B2: Name of Charity | C2: Amount of Contribution | D2: Comment
A3: 1
A4: 2
A5: 3
A6: 4
A7: 5
A8: 6
A9: 7
A10: 8
A11: 9
A12: 10
A13: 11
A14: 12
B15: TOTAL | C15: =SUM(C3:C14) -> 0
A17: For Non-Cash Contributions
B18: Name of Charity | C18: Fair Market Value of Donation (aggregate value of items in this donation) | D18: Address of Charity | E18: Brief Description of Items Donated (e.g. "Clothes, TV, Desk, Small Appliances"). Note: you are required to keep an itemized list of items donated and value assigned to each | F18: Date of Donation | G18: Date Acquired (Various is a valid answer) | H18: How Acquired | I18: Cost of acquisition OR adjusted basis (this cell only relevant if the item has appreciated since acquisition) | J18: How Valued | K18: Comment
A19: 1 | P19: Purchase | Q19: Appraisal
A20: 2 | P20: Gift | Q20: Average share price
A21: 3 | P21: Inheritance | Q21: Catalog
A22: 4 | P22: Exchange | Q22: Comp Sales
A23: 5 | P23: Created | Q23: Thrift Shop Value
A24: 6 | Q24: Consignment Shop Value
A25: 7
A26: 8
A27: 9
A28: 10
A29: 11
A30: 12
B31: TOTAL | C31: =SUM(C19:C30) -> 0
A33: Sample Non-Cash Contribution Info - This is how you should fill out the above
B34: Name of Charity | C34: Fair Market Value of Donation (aggregate value of items in this donation) | D34: Address of Charity | E34: Brief Description of Items Donated (e.g. "Clothes, TV, Desk, Small Appliances"). Note: you are required to keep an itemized list of items donated and value assigned to each | F34: Date of Donation | G34: Date Acquired (Various is a valid answer) | H34: How Acquired | I34: Cost of acquisition OR adjusted basis (this cell only relevant if the item has appreciated since acquisition) | J34: How Valued | K34: Comment
A35: 1 | B35: Goodwill | C35: 565 | D35: 123 Main St., Anytown, XX, 99999 | E35: Baby clothes, small electronics | F35: 45061 | G35: Various | H35: Purchase | I35: N/A | J35: Thrift Shop Value | K35: Receipt attached

Sheet QualifiedChildcare
B1: Provider Info | F1: Amount Paid For Care For Each Child At This Provider
B2: Provider Name | C2: Provider Tax ID / SSN | D2: Provider Address | E2: Provider Phone | F2: =IF(PersonalInfo!B28="","",PersonalInfo!B28) | G2: =IF(PersonalInfo!C28="","",PersonalInfo!C28) | H2: =IF(PersonalInfo!B40="","",PersonalInfo!B40) | I2: =IF(PersonalInfo!C40="","",PersonalInfo!C40) | J2: =IF(PersonalInfo!B52="","",PersonalInfo!B52) | K2: =IF(PersonalInfo!C52="","",PersonalInfo!C52) | L2: =IF(PersonalInfo!B64="","",PersonalInfo!B64) | M2: =IF(PersonalInfo!C64="","",PersonalInfo!C64) | N2: Total All Children
A3: 1 | N3: =SUM(F3:M3) -> 0
A4: 2 | N4: =SUM(F4:M4) -> 0
A5: 3 | N5: =SUM(F5:M5) -> 0
A6: 4 | N6: =SUM(F6:M6) -> 0
B7: TOTAL ALL PROVIDERS | F7: =SUM(F3:F6) -> 0 | G7: =SUM(G3:G6) -> 0 | H7: =SUM(H3:H6) -> 0 | I7: =SUM(I3:I6) -> 0 | J7: =SUM(J3:J6) -> 0 | K7: =SUM(K3:K6) -> 0 | L7: =SUM(L3:L6) -> 0 | M7: =SUM(M3:M6) -> 0 | N7: =SUM(N3:N6) -> 0
B8: Note: You must enter comumn B, C, D, E, and the amount paid by child for each provider. Failure to provide the tax id, address, or phone will result in an email asking for this information. Please enter it here before submitting to avoid the back and forth.
B12: SAMPLE - this is how you should fill out the info above
B13: Provider Info | F13: Amount Paid For Care For Each Child At This Provider
B14: Provider Name | C14: Provider Tax ID / SSN | D14: Provider Address | E14: Provider Phone | F14: Child 1 | G14: Child 2 | H14: Child 3 | I14: =IF(PersonalInfo!C52="","",PersonalInfo!C52) | J14: =IF(PersonalInfo!B64="","",PersonalInfo!B64) | K14: =IF(PersonalInfo!C64="","",PersonalInfo!C64) | L14: =IF(PersonalInfo!B76="","",PersonalInfo!B76) | M14: =IF(PersonalInfo!C76="","",PersonalInfo!C76) | N14: Total All Children
A15: 1 | B15: ABC Childcare | C15: 12-3456789 | D15: 123 Main St., Anytown, ST, 98765 | E15: 555-555-1234 | F15: 14000 | G15: 2000 | N15: =SUM(F15:M15) -> 16000
A16: 2 | B16: XYZ Childcare | C16: 98-7654321 | D16: 987 1st Ave., Springfield, ZZ, 12345 | E16: 555-555-9876 | F16: 2000 | G16: 8000 | H16: 5000 | N16: =SUM(F16:M16) -> 15000
A17: 3 | N17: =SUM(F17:M17) -> 0
A18: 4 | N18: =SUM(F18:M18) -> 0
B19: TOTAL ALL PROVIDERS | F19: =SUM(F15:F18) -> 16000 | G19: =SUM(G15:G18) -> 10000 | H19: =SUM(H15:H18) -> 5000 | I19: =SUM(I15:I18) -> 0 | J19: =SUM(J15:J18) -> 0 | K19: =SUM(K15:K18) -> 0 | L19: =SUM(L15:L18) -> 0 | M19: =SUM(M15:M18) -> 0 | N19: =SUM(N15:N18) -> 31000

Sheet ChildTaxCredit
A1: The following are tax preparer due dilligence questions that must be answered by the taxpayer prior to filing for the Child Tax Credit
A2: Indicate yes/no response with 'x' in the appropriate cell. Provide additional detail in the Comment field as required for each question.
A3: Question | B3: Yes | C3: No | D3: Comment
A4: Can you provide documentation that shows that all of your children are your children, lived with you for more than half the year, and didn't provide more than half of their own support for the year (not asking you to provide it, just asking if you can provide it)?
A5: Did you ever claim the Child Tax Credit or Additional Child Tax Credit in a previous year only to have the IRS disallow your claim at a later date?
A6: Is there any other person who can claim your children as their dependent?
A7: Have you "released claim" for the Child Tax Credit or Additional Child Tax Credit to another person such as an ex-spouse?
A8: Are all children citizens of the US?
